{"name": "test[1]", "status": "failed", "statusDetails": {"message": "AssertionError: assert 12 > 100", "trace": "self = <test_demo.Test_Add object at 0x000001A9563FACF8>\n\n    def test(self):\n>       assert 12 > 100\nE       assert 12 > 100\n\ntest_demo.py:19: AssertionError"}, "parameters": [{"name": "func", "value": "1"}], "start": 1654609074410, "stop": 1654609074410, "uuid": "2ff22ae6-7347-4782-989d-f52b057c0177", "historyId": "e0676b6654dd9f5bd9511a9bec7dabe7", "testCaseId": "82f1dfe168ae6ceb9843031a50de9bc8", "fullName": "test_demo.Test_Add#test", "labels": [{"name": "suite", "value": "test_demo"}, {"name": "subSuite", "value": "Test_Add"}, {"name": "host", "value": "DESKTOP-ROGER"}, {"name": "thread", "value": "8164-MainThread"}, {"name": "framework", "value": "pytest"}, {"name": "language", "value": "cpython3"}, {"name": "package", "value": "test_demo"}]}