{"name": "test[2]", "status": "failed", "statusDetails": {"message": "AssertionError: assert 12 > 100", "trace": "self = <test_demo.Test_Add object at 0x000001A9563FA9E8>\n\n    def test(self):\n>       assert 12 > 100\nE       assert 12 > 100\n\ntest_demo.py:19: AssertionError"}, "parameters": [{"name": "func", "value": "2"}], "start": 1654609074515, "stop": 1654609074515, "uuid": "a62a6b6c-4626-49ab-80c0-c4af2d106328", "historyId": "bb383731cabdc9035ee3384454195b5b", "testCaseId": "82f1dfe168ae6ceb9843031a50de9bc8", "fullName": "test_demo.Test_Add#test", "labels": [{"name": "suite", "value": "test_demo"}, {"name": "subSuite", "value": "Test_Add"}, {"name": "host", "value": "DESKTOP-ROGER"}, {"name": "thread", "value": "8164-MainThread"}, {"name": "framework", "value": "pytest"}, {"name": "language", "value": "cpython3"}, {"name": "package", "value": "test_demo"}]}