{"name": "test[3]", "status": "failed", "statusDetails": {"message": "AssertionError: assert 12 > 100", "trace": "self = <test_demo.Test_Add object at 0x000001A9563FA4E0>\n\n    def test(self):\n>       assert 12 > 100\nE       assert 12 > 100\n\ntest_demo.py:19: AssertionError"}, "parameters": [{"name": "func", "value": "3"}], "start": 1654609074525, "stop": 1654609074526, "uuid": "fac0830a-277a-4a5c-95f9-c4f3964f1608", "historyId": "c983803be16977dc4f22f17fd878bb3f", "testCaseId": "82f1dfe168ae6ceb9843031a50de9bc8", "fullName": "test_demo.Test_Add#test", "labels": [{"name": "suite", "value": "test_demo"}, {"name": "subSuite", "value": "Test_Add"}, {"name": "host", "value": "DESKTOP-ROGER"}, {"name": "thread", "value": "8164-MainThread"}, {"name": "framework", "value": "pytest"}, {"name": "language", "value": "cpython3"}, {"name": "package", "value": "test_demo"}]}