{"name": "test[4]", "status": "failed", "statusDetails": {"message": "AssertionError: assert 12 > 100", "trace": "self = <test_demo.Test_Add object at 0x000001A9563FA8D0>\n\n    def test(self):\n>       assert 12 > 100\nE       assert 12 > 100\n\ntest_demo.py:19: AssertionError"}, "parameters": [{"name": "func", "value": "4"}], "start": 1654609074535, "stop": 1654609074535, "uuid": "a93775cd-52ba-4d8b-bd97-7b1e39a38d73", "historyId": "eac4a713e2d89cd15cfdbf2363b1bdba", "testCaseId": "82f1dfe168ae6ceb9843031a50de9bc8", "fullName": "test_demo.Test_Add#test", "labels": [{"name": "suite", "value": "test_demo"}, {"name": "subSuite", "value": "Test_Add"}, {"name": "host", "value": "DESKTOP-ROGER"}, {"name": "thread", "value": "8164-MainThread"}, {"name": "framework", "value": "pytest"}, {"name": "language", "value": "cpython3"}, {"name": "package", "value": "test_demo"}]}